<?xml version="1.0" ?>
<robot name="hand" xmlns:xacro="http://www.ros.org/wiki/xacro">

<xacro:include filename="$(find hand_description)/urdf/materials.xacro" />
<xacro:include filename="$(find hand_description)/urdf/hand.trans" />
<xacro:include filename="$(find hand_description)/urdf/hand.gazebo" />
<link name="base_link">
  <inertial>
    <origin rpy="0 0 0" xyz="0.0 0.000999999999999985 0.04000000000000004"/>
    <mass value="0.123088"/>
    <inertia ixx="6.6e-05" ixy="-0.0" ixz="-0.0" iyy="0.000164" iyz="0.0" izz="9.9e-05"/>
  </inertial>
  <visual>
    <origin rpy="0 0 0" xyz="0 0 0"/>
    <geometry>
      <mesh filename="package://hand_description/meshes/base_link.stl" scale="0.001 0.001 0.001"/>
    </geometry>
    <material name="steel_satin"/>
  </visual>
  <collision>
    <origin rpy="0 0 0" xyz="0 0 0"/>
    <geometry>
      <mesh filename="package://hand_description/meshes/base_link.stl" scale="0.001 0.001 0.001"/>
    </geometry>
  </collision>
</link>

<link name="cmc_link_v4_1">
  <inertial>
    <origin rpy="0 0 0" xyz="-0.00048645427795625945 -0.004769447524329848 -6.493517695722872e-06"/>
    <mass value="0.018416700517789007"/>
    <inertia ixx="5e-06" ixy="-0.0" ixz="0.0" iyy="5e-06" iyz="-0.0" izz="0.0"/>
  </inertial>
  <visual>
    <origin rpy="0 0 0" xyz="-0.039 0.0 -0.0225"/>
    <geometry>
      <mesh filename="package://hand_description/meshes/cmc_link_v4_1.stl" scale="0.001 0.001 0.001"/>
    </geometry>
    <material name="steel_satin"/>
  </visual>
  <collision>
    <origin rpy="0 0 0" xyz="-0.039 0.0 -0.0225"/>
    <geometry>
      <mesh filename="package://hand_description/meshes/cmc_link_v4_1.stl" scale="0.001 0.001 0.001"/>
    </geometry>
  </collision>
</link>

<link name="t_connector_1_v1_1">
  <inertial>
    <origin rpy="0 0 0" xyz="0.007499999970143861 -1.312864400526692e-11 -0.0012499999999999768"/>
    <mass value="0.00374307805216622"/>
    <inertia ixx="0.0" ixy="-0.0" ixz="-0.0" iyy="0.0" iyz="-0.0" izz="0.0"/>
  </inertial>
  <visual>
    <origin rpy="0 0 0" xyz="-0.03825 0.007 -0.0225"/>
    <geometry>
      <mesh filename="package://hand_description/meshes/t_connector_1_v1_1.stl" scale="0.001 0.001 0.001"/>
    </geometry>
    <material name="steel_satin"/>
  </visual>
  <collision>
    <origin rpy="0 0 0" xyz="-0.03825 0.007 -0.0225"/>
    <geometry>
      <mesh filename="package://hand_description/meshes/t_connector_1_v1_1.stl" scale="0.001 0.001 0.001"/>
    </geometry>
  </collision>
</link>

<link name="t_mcp_v5_1">
  <inertial>
    <origin rpy="0 0 0" xyz="0.007807400362975329 0.002936289856962501 -0.00016613310844226098"/>
    <mass value="0.03943050014537037"/>
    <inertia ixx="1.1e-05" ixy="-0.0" ixz="0.0" iyy="1.3e-05" iyz="-0.0" izz="3e-06"/>
  </inertial>
  <visual>
    <origin rpy="0 0 0" xyz="-0.05325 0.007 -0.0225"/>
    <geometry>
      <mesh filename="package://hand_description/meshes/t_mcp_v5_1.stl" scale="0.001 0.001 0.001"/>
    </geometry>
    <material name="steel_satin"/>
  </visual>
  <collision>
    <origin rpy="0 0 0" xyz="-0.05325 0.007 -0.0225"/>
    <geometry>
      <mesh filename="package://hand_description/meshes/t_mcp_v5_1.stl" scale="0.001 0.001 0.001"/>
    </geometry>
  </collision>
</link>

<link name="t_pip_link_v5_1">
  <inertial>
    <origin rpy="0 0 0" xyz="0.021556157971685322 -0.006243616814845158 2.555247680113837e-15"/>
    <mass value="0.03216718051096679"/>
    <inertia ixx="2e-06" ixy="1e-06" ixz="0.0" iyy="7e-06" iyz="-0.0" izz="6e-06"/>
  </inertial>
  <visual>
    <origin rpy="0 0 0" xyz="-0.072947 0.004197 -0.014"/>
    <geometry>
      <mesh filename="package://hand_description/meshes/t_pip_link_v5_1.stl" scale="0.001 0.001 0.001"/>
    </geometry>
    <material name="steel_satin"/>
  </visual>
  <collision>
    <origin rpy="0 0 0" xyz="-0.072947 0.004197 -0.014"/>
    <geometry>
      <mesh filename="package://hand_description/meshes/t_pip_link_v5_1.stl" scale="0.001 0.001 0.001"/>
    </geometry>
  </collision>
</link>

<link name="t_connector_2_v1_1">
  <inertial>
    <origin rpy="0 0 0" xyz="0.00749969926025644 3.0084577047270744e-07 -0.0012499999999999543"/>
    <mass value="0.00374307805216622"/>
    <inertia ixx="0.0" ixy="0.0" ixz="0.0" iyy="0.0" iyz="0.0" izz="0.0"/>
  </inertial>
  <visual>
    <origin rpy="0 0 0" xyz="-0.108947 0.013197 -0.014"/>
    <geometry>
      <mesh filename="package://hand_description/meshes/t_connector_2_v1_1.stl" scale="0.001 0.001 0.001"/>
    </geometry>
    <material name="steel_satin"/>
  </visual>
  <collision>
    <origin rpy="0 0 0" xyz="-0.108947 0.013197 -0.014"/>
    <geometry>
      <mesh filename="package://hand_description/meshes/t_connector_2_v1_1.stl" scale="0.001 0.001 0.001"/>
    </geometry>
  </collision>
</link>

<link name="t_tip_v2_1">
  <inertial>
    <origin rpy="0 0 0" xyz="0.001140939821871606 7.444969044555216e-08 0.002500000000000042"/>
    <mass value="0.011962131611831003"/>
    <inertia ixx="1e-06" ixy="-0.0" ixz="0.0" iyy="1e-06" iyz="0.0" izz="0.0"/>
  </inertial>
  <visual>
    <origin rpy="0 0 0" xyz="-0.123947 0.013197 -0.0115"/>
    <geometry>
      <mesh filename="package://hand_description/meshes/t_tip_v2_1.stl" scale="0.001 0.001 0.001"/>
    </geometry>
    <material name="steel_satin"/>
  </visual>
  <collision>
    <origin rpy="0 0 0" xyz="-0.123947 0.013197 -0.0115"/>
    <geometry>
      <mesh filename="package://hand_description/meshes/t_tip_v2_1.stl" scale="0.001 0.001 0.001"/>
    </geometry>
  </collision>
</link>

<link name="i_mcp_yaw_link_v1_1">
  <inertial>
    <origin rpy="0 0 0" xyz="-3.172462292866385e-14 -0.0012359787607253364 0.0005366094686043744"/>
    <mass value="0.011430485562037091"/>
    <inertia ixx="2e-06" ixy="-0.0" ixz="0.0" iyy="3e-06" iyz="0.0" izz="0.0"/>
  </inertial>
  <visual>
    <origin rpy="0 0 0" xyz="-0.0195 0.0 -0.0225"/>
    <geometry>
      <mesh filename="package://hand_description/meshes/i_mcp_yaw_link_v1_1.stl" scale="0.001 0.001 0.001"/>
    </geometry>
    <material name="steel_satin"/>
  </visual>
  <collision>
    <origin rpy="0 0 0" xyz="-0.0195 0.0 -0.0225"/>
    <geometry>
      <mesh filename="package://hand_description/meshes/i_mcp_yaw_link_v1_1.stl" scale="0.001 0.001 0.001"/>
    </geometry>
  </collision>
</link>

<link name="i_mcp_pitch_link_v1_1">
  <inertial>
    <origin rpy="0 0 0" xyz="-4.277828091758806e-15 -0.0056166169131739024 0.02492246034961377"/>
    <mass value="0.028244047864773934"/>
    <inertia ixx="6e-06" ixy="0.0" ixz="-0.0" iyy="6e-06" iyz="0.0" izz="2e-06"/>
  </inertial>
  <visual>
    <origin rpy="0 0 0" xyz="-0.0195 0.002 -0.0405"/>
    <geometry>
      <mesh filename="package://hand_description/meshes/i_mcp_pitch_link_v1_1.stl" scale="0.001 0.001 0.001"/>
    </geometry>
    <material name="steel_satin"/>
  </visual>
  <collision>
    <origin rpy="0 0 0" xyz="-0.0195 0.002 -0.0405"/>
    <geometry>
      <mesh filename="package://hand_description/meshes/i_mcp_pitch_link_v1_1.stl" scale="0.001 0.001 0.001"/>
    </geometry>
  </collision>
</link>

<link name="i_connector_1_v1_1">
  <inertial>
    <origin rpy="0 0 0" xyz="0.0012500000000000011 -3.469446951953614e-17 0.007499999970251525"/>
    <mass value="0.00374307805216622"/>
    <inertia ixx="0.0" ixy="0.0" ixz="-0.0" iyy="0.0" iyz="0.0" izz="0.0"/>
  </inertial>
  <visual>
    <origin rpy="0 0 0" xyz="-0.0195 0.00925 -0.0815"/>
    <geometry>
      <mesh filename="package://hand_description/meshes/i_connector_1_v1_1.stl" scale="0.001 0.001 0.001"/>
    </geometry>
    <material name="steel_satin"/>
  </visual>
  <collision>
    <origin rpy="0 0 0" xyz="-0.0195 0.00925 -0.0815"/>
    <geometry>
      <mesh filename="package://hand_description/meshes/i_connector_1_v1_1.stl" scale="0.001 0.001 0.001"/>
    </geometry>
  </collision>
</link>

<link name="i_pip_pitch_link_v4_1">
  <inertial>
    <origin rpy="0 0 0" xyz="3.469446951953614e-18 0.001096507521878223 0.018000000026317478"/>
    <mass value="0.0314105238001653"/>
    <inertia ixx="7e-06" ixy="-0.0" ixz="0.0" iyy="8e-06" iyz="-0.0" izz="2e-06"/>
  </inertial>
  <visual>
    <origin rpy="0 0 0" xyz="-0.0195 0.00925 -0.0965"/>
    <geometry>
      <mesh filename="package://hand_description/meshes/i_pip_pitch_link_v4_1.stl" scale="0.001 0.001 0.001"/>
    </geometry>
    <material name="steel_satin"/>
  </visual>
  <collision>
    <origin rpy="0 0 0" xyz="-0.0195 0.00925 -0.0965"/>
    <geometry>
      <mesh filename="package://hand_description/meshes/i_pip_pitch_link_v4_1.stl" scale="0.001 0.001 0.001"/>
    </geometry>
  </collision>
</link>

<link name="i_connector_2_v1_1">
  <inertial>
    <origin rpy="0 0 0" xyz="0.0012500000000000011 -5.204170427930421e-17 0.007499999970251553"/>
    <mass value="0.00374307805216622"/>
    <inertia ixx="0.0" ixy="0.0" ixz="0.0" iyy="0.0" iyz="0.0" izz="0.0"/>
  </inertial>
  <visual>
    <origin rpy="0 0 0" xyz="-0.0195 0.00925 -0.1325"/>
    <geometry>
      <mesh filename="package://hand_description/meshes/i_connector_2_v1_1.stl" scale="0.001 0.001 0.001"/>
    </geometry>
    <material name="steel_satin"/>
  </visual>
  <collision>
    <origin rpy="0 0 0" xyz="-0.0195 0.00925 -0.1325"/>
    <geometry>
      <mesh filename="package://hand_description/meshes/i_connector_2_v1_1.stl" scale="0.001 0.001 0.001"/>
    </geometry>
  </collision>
</link>

<link name="i_dip_link_v2_1">
  <inertial>
    <origin rpy="0 0 0" xyz="2.28538777867493e-08 0.0006333260004305185 0.005499983676315989"/>
    <mass value="0.0165936992661325"/>
    <inertia ixx="1e-06" ixy="0.0" ixz="0.0" iyy="1e-06" iyz="-0.0" izz="1e-06"/>
  </inertial>
  <visual>
    <origin rpy="0 0 0" xyz="-0.0195 0.00925 -0.1475"/>
    <geometry>
      <mesh filename="package://hand_description/meshes/i_dip_link_v2_1.stl" scale="0.001 0.001 0.001"/>
    </geometry>
    <material name="steel_satin"/>
  </visual>
  <collision>
    <origin rpy="0 0 0" xyz="-0.0195 0.00925 -0.1475"/>
    <geometry>
      <mesh filename="package://hand_description/meshes/i_dip_link_v2_1.stl" scale="0.001 0.001 0.001"/>
    </geometry>
  </collision>
</link>

<link name="i_connector_3_v1_1">
  <inertial>
    <origin rpy="0 0 0" xyz="-0.0012499999999999838 -7.806255641895632e-17 0.007499999970251553"/>
    <mass value="0.00374307805216622"/>
    <inertia ixx="0.0" ixy="0.0" ixz="0.0" iyy="0.0" iyz="-0.0" izz="0.0"/>
  </inertial>
  <visual>
    <origin rpy="0 0 0" xyz="-0.0195 0.00925 -0.1585"/>
    <geometry>
      <mesh filename="package://hand_description/meshes/i_connector_3_v1_1.stl" scale="0.001 0.001 0.001"/>
    </geometry>
    <material name="steel_satin"/>
  </visual>
  <collision>
    <origin rpy="0 0 0" xyz="-0.0195 0.00925 -0.1585"/>
    <geometry>
      <mesh filename="package://hand_description/meshes/i_connector_3_v1_1.stl" scale="0.001 0.001 0.001"/>
    </geometry>
  </collision>
</link>

<link name="i_tip_link_v2_1">
  <inertial>
    <origin rpy="0 0 0" xyz="-2.285387776246317e-08 -0.0006333260004306746 0.005499983676315989"/>
    <mass value="0.0165936992661325"/>
    <inertia ixx="1e-06" ixy="0.0" ixz="-0.0" iyy="1e-06" iyz="0.0" izz="1e-06"/>
  </inertial>
  <visual>
    <origin rpy="0 0 0" xyz="-0.0195 0.00925 -0.1735"/>
    <geometry>
      <mesh filename="package://hand_description/meshes/i_tip_link_v2_1.stl" scale="0.001 0.001 0.001"/>
    </geometry>
    <material name="steel_satin"/>
  </visual>
  <collision>
    <origin rpy="0 0 0" xyz="-0.0195 0.00925 -0.1735"/>
    <geometry>
      <mesh filename="package://hand_description/meshes/i_tip_link_v2_1.stl" scale="0.001 0.001 0.001"/>
    </geometry>
  </collision>
</link>

<joint name="Rigid1" type="fixed">
  <origin rpy="0 0 0" xyz="0.039 0.0 0.0225"/>
  <parent link="base_link"/>
  <child link="cmc_link_v4_1"/>
</joint>

<joint name="Rev2" type="continuous">
  <origin rpy="0 0 0" xyz="-0.00075 -0.007 0.0"/>
  <parent link="cmc_link_v4_1"/>
  <child link="t_connector_1_v1_1"/>
  <axis xyz="0.0 0.0 -1.0"/>
</joint>

<joint name="Rigid3" type="fixed">
  <origin rpy="0 0 0" xyz="0.015 0.0 0.0"/>
  <parent link="t_connector_1_v1_1"/>
  <child link="t_mcp_v5_1"/>
</joint>

<joint name="Rev4" type="continuous">
  <origin rpy="0 0 0" xyz="0.019697 0.002803 -0.0085"/>
  <parent link="t_mcp_v5_1"/>
  <child link="t_pip_link_v5_1"/>
  <axis xyz="0.0 -1.0 -0.0"/>
</joint>

<joint name="Rev5" type="continuous">
  <origin rpy="0 0 0" xyz="0.036 -0.009 0.0"/>
  <parent link="t_pip_link_v5_1"/>
  <child link="t_connector_2_v1_1"/>
  <axis xyz="-0.0 0.0 -1.0"/>
</joint>

<joint name="Rev6" type="continuous">
  <origin rpy="0 0 0" xyz="0.015 0.0 -0.0025"/>
  <parent link="t_connector_2_v1_1"/>
  <child link="t_tip_v2_1"/>
  <axis xyz="-0.0 0.0 -1.0"/>
</joint>

<joint name="Rigid7" type="fixed">
  <origin rpy="0 0 0" xyz="0.0195 0.0 0.0225"/>
  <parent link="base_link"/>
  <child link="i_mcp_yaw_link_v1_1"/>
</joint>

<joint name="Rev8" type="continuous">
  <origin rpy="0 0 0" xyz="0.0 -0.002 0.018"/>
  <parent link="i_mcp_yaw_link_v1_1"/>
  <child link="i_mcp_pitch_link_v1_1"/>
  <axis xyz="0.0 -1.0 -0.0"/>
</joint>

<joint name="Rev9" type="continuous">
  <origin rpy="0 0 0" xyz="0.0 -0.00725 0.041"/>
  <parent link="i_mcp_pitch_link_v1_1"/>
  <child link="i_connector_1_v1_1"/>
  <axis xyz="-1.0 0.0 0.0"/>
</joint>

<joint name="Rigid11" type="fixed">
  <origin rpy="0 0 0" xyz="0.0 0.0 0.015"/>
  <parent link="i_connector_1_v1_1"/>
  <child link="i_pip_pitch_link_v4_1"/>
</joint>

<joint name="Rev12" type="continuous">
  <origin rpy="0 0 0" xyz="0.0 0.0 0.036"/>
  <parent link="i_pip_pitch_link_v4_1"/>
  <child link="i_connector_2_v1_1"/>
  <axis xyz="-1.0 0.0 0.0"/>
</joint>

<joint name="Rigid16" type="fixed">
  <origin rpy="0 0 0" xyz="0.0 0.0 0.015"/>
  <parent link="i_connector_2_v1_1"/>
  <child link="i_dip_link_v2_1"/>
</joint>

<joint name="Rev17" type="continuous">
  <origin rpy="0 0 0" xyz="0.0 0.0 0.011"/>
  <parent link="i_dip_link_v2_1"/>
  <child link="i_connector_3_v1_1"/>
  <axis xyz="1.0 -0.0 -0.0"/>
</joint>

<joint name="Rigid18" type="fixed">
  <origin rpy="0 0 0" xyz="0.0 0.0 0.015"/>
  <parent link="i_connector_3_v1_1"/>
  <child link="i_tip_link_v2_1"/>
</joint>

</robot>
