<?xml version="1.0" ?>
<robot name="arm" xmlns:xacro="http://www.ros.org/wiki/xacro">

<xacro:include filename="$(find arm_description)/urdf/materials.xacro" />
<xacro:include filename="$(find arm_description)/urdf/arm.trans" />
<xacro:include filename="$(find arm_description)/urdf/arm.gazebo" />
<link name="base_link">
  <inertial>
    <origin rpy="0 0 0" xyz="0.045004269594343685 0.14080314103611938 -0.04418171946780986"/>
    <mass value="0.5918760559363156"/>
    <inertia ixx="0.000384" ixy="-6.2e-05" ixz="0.0" iyy="0.000725" iyz="0.0" izz="0.000373"/>
  </inertial>
  <visual>
    <origin rpy="0 0 0" xyz="0 0 0"/>
    <geometry>
      <mesh filename="package://arm_description/meshes/base_link.stl" scale="0.001 0.001 0.001"/>
    </geometry>
    <material name="steel_satin"/>
  </visual>
  <collision>
    <origin rpy="0 0 0" xyz="0 0 0"/>
    <geometry>
      <mesh filename="package://arm_description/meshes/base_link.stl" scale="0.001 0.001 0.001"/>
    </geometry>
  </collision>
</link>

<link name="shoulder_v7_1">
  <inertial>
    <origin rpy="0 0 0" xyz="0.03979482426435912 0.17034737362648983 -0.05392380300504991"/>
    <mass value="0.17928408437421925"/>
    <inertia ixx="7.5e-05" ixy="-0.0" ixz="-0.0" iyy="7.5e-05" iyz="-0.0" izz="7.4e-05"/>
  </inertial>
  <visual>
    <origin rpy="0 0 0" xyz="-0.0 -0.0 -0.01"/>
    <geometry>
      <mesh filename="package://arm_description/meshes/shoulder_v7_1.stl" scale="0.001 0.001 0.001"/>
    </geometry>
    <material name="plastic_glossy_black"/>
  </visual>
  <collision>
    <origin rpy="0 0 0" xyz="-0.0 -0.0 -0.01"/>
    <geometry>
      <mesh filename="package://arm_description/meshes/shoulder_v7_1.stl" scale="0.001 0.001 0.001"/>
    </geometry>
  </collision>
</link>

<link name="elbow_v12_1">
  <inertial>
    <origin rpy="0 0 0" xyz="0.03384303335064815 0.2433766550652839 -0.003553644285581166"/>
    <mass value="0.13164405591331413"/>
    <inertia ixx="0.000352" ixy="2.9e-05" ixz="0.0" iyy="2.4e-05" iyz="-5e-06" izz="0.000367"/>
  </inertial>
  <visual>
    <origin rpy="0 0 0" xyz="-0.0 0.005 -0.0"/>
    <geometry>
      <mesh filename="package://arm_description/meshes/elbow_v12_1.stl" scale="0.001 0.001 0.001"/>
    </geometry>
    <material name="polystyrene"/>
  </visual>
  <collision>
    <origin rpy="0 0 0" xyz="-0.0 0.005 -0.0"/>
    <geometry>
      <mesh filename="package://arm_description/meshes/elbow_v12_1.stl" scale="0.001 0.001 0.001"/>
    </geometry>
  </collision>
</link>

<link name="stepper_motor_v4_1">
  <inertial>
    <origin rpy="0 0 0" xyz="-4.223186543181323e-07 -3.153265071831335e-07 -0.019816764371663013"/>
    <mass value="0.09175959619142068"/>
    <inertia ixx="2.5e-05" ixy="0.0" ixz="-0.0" iyy="2.5e-05" iyz="0.0" izz="2.4e-05"/>
  </inertial>
  <visual>
    <origin rpy="0 0 0" xyz="-0.028465 -0.299853 0.004182"/>
    <geometry>
      <mesh filename="package://arm_description/meshes/stepper_motor_v4_1.stl" scale="0.001 0.001 0.001"/>
    </geometry>
    <material name="plastic_glossy_black"/>
  </visual>
  <collision>
    <origin rpy="0 0 0" xyz="-0.028465 -0.299853 0.004182"/>
    <geometry>
      <mesh filename="package://arm_description/meshes/stepper_motor_v4_1.stl" scale="0.001 0.001 0.001"/>
    </geometry>
  </collision>
</link>

<link name="fist_v8_1">
  <inertial>
    <origin rpy="0 0 0" xyz="0.08545072429578468 0.2965880967939642 0.015786321919730437"/>
    <mass value="0.10436047216159268"/>
    <inertia ixx="9e-06" ixy="-2.8e-05" ixz="-0.0" iyy="0.000325" iyz="-0.0" izz="0.000328"/>
  </inertial>
  <visual>
    <origin rpy="0 0 0" xyz="-0.02 -0.01 -0.0"/>
    <geometry>
      <mesh filename="package://arm_description/meshes/fist_v8_1.stl" scale="0.001 0.001 0.001"/>
    </geometry>
    <material name="plastic_glossy_white"/>
  </visual>
  <collision>
    <origin rpy="0 0 0" xyz="-0.02 -0.01 -0.0"/>
    <geometry>
      <mesh filename="package://arm_description/meshes/fist_v8_1.stl" scale="0.001 0.001 0.001"/>
    </geometry>
  </collision>
</link>

<link name="left_claw_v2_1">
  <inertial>
    <origin rpy="0 0 0" xyz="0.02473385694239269 0.0021638438876491195 -4.570971836950072e-05"/>
    <mass value="0.17536153168700247"/>
    <inertia ixx="1.7e-05" ixy="-2e-06" ixz="0.0" iyy="3.9e-05" iyz="0.0" izz="4.9e-05"/>
  </inertial>
  <visual>
    <origin rpy="0 0 0" xyz="-0.247627 -0.319027 -0.038318"/>
    <geometry>
      <mesh filename="package://arm_description/meshes/left_claw_v2_1.stl" scale="0.001 0.001 0.001"/>
    </geometry>
    <material name="steel_satin"/>
  </visual>
  <collision>
    <origin rpy="0 0 0" xyz="-0.247627 -0.319027 -0.038318"/>
    <geometry>
      <mesh filename="package://arm_description/meshes/left_claw_v2_1.stl" scale="0.001 0.001 0.001"/>
    </geometry>
  </collision>
</link>

<link name="right_claw_v2_1">
  <inertial>
    <origin rpy="0 0 0" xyz="0.0247338569423923 0.0021638438876509514 4.627078276895746e-05"/>
    <mass value="0.17536153168700244"/>
    <inertia ixx="1.7e-05" ixy="-2e-06" ixz="-0.0" iyy="3.9e-05" iyz="-0.0" izz="4.9e-05"/>
  </inertial>
  <visual>
    <origin rpy="0 0 0" xyz="-0.247627 -0.319027 0.006682"/>
    <geometry>
      <mesh filename="package://arm_description/meshes/right_claw_v2_1.stl" scale="0.001 0.001 0.001"/>
    </geometry>
    <material name="steel_satin"/>
  </visual>
  <collision>
    <origin rpy="0 0 0" xyz="-0.247627 -0.319027 0.006682"/>
    <geometry>
      <mesh filename="package://arm_description/meshes/right_claw_v2_1.stl" scale="0.001 0.001 0.001"/>
    </geometry>
  </collision>
</link>

<link name="dc_motor_v3_1">
  <inertial>
    <origin rpy="0 0 0" xyz="0.0124520835993647 0.0010893861436002128 2.8053219981727384e-07"/>
    <mass value="0.09633399347921827"/>
    <inertia ixx="8e-06" ixy="-0.0" ixz="0.0" iyy="9e-06" iyz="-0.0" izz="9e-06"/>
  </inertial>
  <visual>
    <origin rpy="0 0 0" xyz="-0.202799 -0.315105 -0.015818"/>
    <geometry>
      <mesh filename="package://arm_description/meshes/dc_motor_v3_1.stl" scale="0.001 0.001 0.001"/>
    </geometry>
    <material name="steel_satin"/>
  </visual>
  <collision>
    <origin rpy="0 0 0" xyz="-0.202799 -0.315105 -0.015818"/>
    <geometry>
      <mesh filename="package://arm_description/meshes/dc_motor_v3_1.stl" scale="0.001 0.001 0.001"/>
    </geometry>
  </collision>
</link>

<link name="eef_v4_1">
  <inertial>
    <origin rpy="0 0 0" xyz="0.037745306918037874 0.3081623756788047 0.015818280532200014"/>
    <mass value="0.03189621893711599"/>
    <inertia ixx="1.2e-05" ixy="0.0" ixz="-0.0" iyy="1e-05" iyz="0.0" izz="3e-06"/>
  </inertial>
  <visual>
    <origin rpy="0 0 0" xyz="-0.2 -0.01 -0.0"/>
    <geometry>
      <mesh filename="package://arm_description/meshes/eef_v4_1.stl" scale="0.001 0.001 0.001"/>
    </geometry>
    <material name="surface_matte"/>
  </visual>
  <collision>
    <origin rpy="0 0 0" xyz="-0.2 -0.01 -0.0"/>
    <geometry>
      <mesh filename="package://arm_description/meshes/eef_v4_1.stl" scale="0.001 0.001 0.001"/>
    </geometry>
  </collision>
</link>

<joint name="Rev1" type="continuous">
  <origin rpy="0 0 0" xyz="0.0 0.0 0.01"/>
  <parent link="base_link"/>
  <child link="shoulder_v7_1"/>
  <axis xyz="-0.173648 0.984808 0.0"/>
</joint>

<joint name="Rev2" type="continuous">
  <origin rpy="0 0 0" xyz="0.0 -0.005 -0.01"/>
  <parent link="shoulder_v7_1"/>
  <child link="elbow_v12_1"/>
  <axis xyz="0.0 -0.0 1.0"/>
</joint>

<joint name="Rigid3" type="fixed">
  <origin rpy="0 0 0" xyz="0.028465 0.304853 -0.004182"/>
  <parent link="elbow_v12_1"/>
  <child link="stepper_motor_v4_1"/>
</joint>

<joint name="Rev4" type="continuous">
  <origin rpy="0 0 0" xyz="-0.008465 -0.289853 0.004182"/>
  <parent link="stepper_motor_v4_1"/>
  <child link="fist_v8_1"/>
  <axis xyz="0.0 -0.0 1.0"/>
</joint>

<joint name="Slider6" type="prismatic">
  <origin rpy="0 0 0" xyz="0.047627 0.309027 0.038318"/>
  <parent link="eef_v4_1"/>
  <child link="left_claw_v2_1"/>
  <axis xyz="-0.0 0.0 -1.0"/>
  <limit effort="100" lower="0.0" upper="0.0" velocity="100"/>
</joint>

<joint name="Slider7" type="prismatic">
  <origin rpy="0 0 0" xyz="0.047627 0.309027 -0.006682"/>
  <parent link="eef_v4_1"/>
  <child link="right_claw_v2_1"/>
  <axis xyz="-0.0 0.0 -1.0"/>
  <limit effort="100" lower="0.0" upper="0.0" velocity="100"/>
</joint>

<joint name="Rigid8" type="fixed">
  <origin rpy="0 0 0" xyz="0.182799 0.305105 0.015818"/>
  <parent link="fist_v8_1"/>
  <child link="dc_motor_v3_1"/>
</joint>

<joint name="Rev9" type="continuous">
  <origin rpy="0 0 0" xyz="-0.002799 -0.305105 -0.015818"/>
  <parent link="dc_motor_v3_1"/>
  <child link="eef_v4_1"/>
  <axis xyz="0.996195 0.087156 -0.0"/>
</joint>

</robot>
